<?xml version="1.0" ?>
<!-- =================================================================================== -->
<!-- |    This document was autogenerated by xacro from cell.xacro                     | -->
<!-- |    EDITING THIS FILE BY HAND IS NOT RECOMMENDED                                 | -->
<!-- =================================================================================== -->
<robot name="crx20ia_l">
  <link name="world"/>
  <joint name="partent_to_ped" type="fixed">
    <origin rpy="0 0 0" xyz="0 0 0"/>
    <parent link="world"/>
    <child link="pedestal"/>
  </joint>
  <link name="pedestal">
    <visual>
      <origin rpy="0 0 0" xyz="0 0 0.5"/>
      <geometry>
        <box size=".25 .25 1.0"/>
      </geometry>
      <material name="black">
        <color rgba="0 0 0 1"/>
      </material>
    </visual>
    <collision>
      <origin rpy="0 0 0" xyz="0 0 0.5"/>
      <geometry>
        <box size=".25 .25 1.0"/>
      </geometry>
    </collision>
  </link>
  <link name="pedestal_mounting"/>
  <joint name="mounting" type="fixed">
    <origin rpy="0 0 0" xyz="0 0 1.0"/>
    <parent link="pedestal"/>
    <child link="pedestal_mounting"/>
  </joint>
  <joint name="base_to_robot" type="fixed">
    <origin rpy="0 0 0" xyz="0 0 0"/>
    <parent link="pedestal_mounting"/>
    <child link="base_link"/>
  </joint>
  <!-- Read only parameter should allow to move the robot via manual guidance, jog, etc throu the TP, and makes available the /joint_states topic -->
  <ros2_control name="crx20" type="system">
    <hardware>
      <plugin>mock_components/GenericSystem</plugin>
      <!-- <param name="position_state_following_offset">0.1</param> -->
    </hardware>
    <joint name="J1">
      <command_interface name="position">
        <param name="min">{-2*pi}</param>
        <param name="max">{2*pi}</param>
      </command_interface>
      <!-- <command_interface name="velocity">
          <param name="min">-3.15</param>
          <param name="max">3.15</param>
        </command_interface> -->
      <state_interface name="position">
        <param name="initial_value">0.0</param>
      </state_interface>
      <state_interface name="velocity"/>
    </joint>
    <joint name="J2">
      <command_interface name="position">
        <param name="min">{-2*pi}</param>
        <param name="max">{2*pi}</param>
      </command_interface>
      <!-- <command_interface name="velocity">
          <param name="min">-3.15</param>
          <param name="max">3.15</param>
        </command_interface> -->
      <state_interface name="position">
        <param name="initial_value">0.0</param>
      </state_interface>
      <state_interface name="velocity"/>
    </joint>
    <joint name="J3">
      <command_interface name="position">
        <param name="min">{-pi}</param>
        <param name="max">{pi}</param>
      </command_interface>
      <!-- <command_interface name="velocity">
          <param name="min">-3.15</param>
          <param name="max">3.15</param>
        </command_interface> -->
      <state_interface name="position">
        <param name="initial_value">0.0</param>
      </state_interface>
      <state_interface name="velocity"/>
    </joint>
    <joint name="J4">
      <command_interface name="position">
        <param name="min">{-2*pi}</param>
        <param name="max">{2*pi}</param>
      </command_interface>
      <!-- <command_interface name="velocity">
          <param name="min">-3.2</param>
          <param name="max">3.2</param>
        </command_interface> -->
      <state_interface name="position">
        <param name="initial_value">0.0</param>
      </state_interface>
      <state_interface name="velocity"/>
    </joint>
    <joint name="J5">
      <command_interface name="position">
        <param name="min">{-2*pi}</param>
        <param name="max">{2*pi}</param>
      </command_interface>
      <!-- <command_interface name="velocity">
          <param name="min">-3.2</param>
          <param name="max">3.2</param>
        </command_interface> -->
      <state_interface name="position">
        <param name="initial_value">0.0</param>
      </state_interface>
      <state_interface name="velocity"/>
    </joint>
    <joint name="J6">
      <command_interface name="position">
        <param name="min">{-2*pi}</param>
        <param name="max">{2*pi}</param>
      </command_interface>
      <!-- <command_interface name="velocity">
          <param name="min">-3.2</param>
          <param name="max">3.2</param>
        </command_interface> -->
      <state_interface name="position">
        <param name="initial_value">0.0</param>
      </state_interface>
      <state_interface name="velocity"/>
    </joint>
  </ros2_control>
  <material name="FANUC_Black">
    <color rgba="0 0 0 1.0"/>
  </material>
  <material name="FANUC_Yellow">
    <color rgba="1.00 0.84 0.01 1.00"/>
  </material>
  <material name="FANUC_Green">
    <color rgba="0.43 0.68 0.26 1.00"/>
  </material>
  <material name="FANUC_White">
    <color rgba="0.84 0.84 0.82 1.00"/>
  </material>
  <!-- links -->
  <link name="base_link">
    <visual>
      <origin rpy="0 0 0" xyz="0 0 0"/>
      <geometry>
        <mesh filename="package://crx_description/meshes/crx20ia_l/visual/base.stl" scale="0.001 0.001 0.001"/>
      </geometry>
      <material name="FANUC_Black"/>
    </visual>
    <collision>
      <origin rpy="0 0 0" xyz="0 0 0"/>
      <geometry>
        <mesh filename="package://crx_description/meshes/crx20ia_l/collision/base.stl" scale="0.001 0.001 0.001"/>
      </geometry>
    </collision>
  </link>
  <link name="J1_link">
    <visual>
      <origin rpy="0 0 0" xyz="0 0 -0.11729999999999999"/>
      <geometry>
        <mesh filename="package://crx_description/meshes/crx20ia_l/visual/j1.stl" scale="0.001 0.001 0.001"/>
      </geometry>
      <material name="FANUC_White"/>
    </visual>
    <collision>
      <origin rpy="0 0 0" xyz="0 0 -0.11729999999999999"/>
      <geometry>
        <mesh filename="package://crx_description/meshes/crx20ia_l/collision/j1.stl" scale="0.001 0.001 0.001"/>
      </geometry>
    </collision>
  </link>
  <link name="J2_link">
    <visual>
      <origin rpy="0 0 0" xyz="-0.0 0 0.0"/>
      <geometry>
        <mesh filename="package://crx_description/meshes/crx20ia_l/visual/j2.stl" scale="0.001 0.001 0.001"/>
      </geometry>
      <material name="FANUC_White"/>
    </visual>
    <collision>
      <origin rpy="0 0 0" xyz="-0.0 0 0.0"/>
      <geometry>
        <mesh filename="package://crx_description/meshes/crx20ia_l/collision/j2.stl" scale="0.001 0.001 0.001"/>
      </geometry>
    </collision>
  </link>
  <link name="J3_link">
    <visual>
      <origin rpy="0 0 0" xyz="-0.0 0 0.0"/>
      <geometry>
        <mesh filename="package://crx_description/meshes/crx20ia_l/visual/j3.stl" scale="0.001 0.001 0.001"/>
      </geometry>
      <material name="FANUC_White"/>
    </visual>
    <collision>
      <origin rpy="0 0 0" xyz="-0.0 0 0.0"/>
      <geometry>
        <mesh filename="package://crx_description/meshes/crx20ia_l/collision/j3.stl" scale="0.001 0.001 0.001"/>
      </geometry>
    </collision>
  </link>
  <link name="J4_link">
    <visual>
      <origin rpy="0 0 0" xyz="0.54 0 0.0"/>
      <geometry>
        <mesh filename="package://crx_description/meshes/crx20ia_l/visual/j4.stl" scale="0.001 0.001 0.001"/>
      </geometry>
      <material name="FANUC_White"/>
    </visual>
    <collision>
      <origin rpy="0 0 0" xyz="0.54 0 0.0"/>
      <geometry>
        <mesh filename="package://crx_description/meshes/crx20ia_l/collision/j4.stl" scale="0.001 0.001 0.001"/>
      </geometry>
    </collision>
  </link>
  <link name="J5_link">
    <visual>
      <origin rpy="0 0 0" xyz="0.0 -0.15 0.0"/>
      <geometry>
        <mesh filename="package://crx_description/meshes/crx20ia_l/visual/j5.stl" scale="0.001 0.001 0.001"/>
      </geometry>
      <material name="FANUC_White"/>
    </visual>
    <collision>
      <origin rpy="0 0 0" xyz="0.0 -0.15 0.0"/>
      <geometry>
        <mesh filename="package://crx_description/meshes/crx20ia_l/collision/j5.stl" scale="0.001 0.001 0.001"/>
      </geometry>
    </collision>
  </link>
  <link name="J6_link">
    <visual>
      <origin rpy="0 0 0" xyz="0.15999999999999992 0.0 0.0"/>
      <geometry>
        <mesh filename="package://crx_description/meshes/crx20ia_l/visual/j6.stl" scale="0.001 0.001 0.001"/>
      </geometry>
      <material name="FANUC_Black"/>
    </visual>
    <collision>
      <origin rpy="0 0 0" xyz="0.15999999999999992 0.0 0.0"/>
      <geometry>
        <mesh filename="package://crx_description/meshes/crx20ia_l/collision/j6.stl" scale="0.001 0.001 0.001"/>
      </geometry>
    </collision>
  </link>
  <!-- joints -->
  <joint name="J1" type="revolute">
    <origin rpy="0 0 0" xyz="0 0 0.245"/>
    <parent link="base_link"/>
    <child link="J1_link"/>
    <axis xyz="0 0 1"/>
    <limit effort="0" lower="-3.139847324337799" upper="3.139847324337799" velocity="1.3962634015954636"/>
  </joint>
  <joint name="J2" type="revolute">
    <origin rpy="0 0 0" xyz="0.0 0 0"/>
    <parent link="J1_link"/>
    <child link="J2_link"/>
    <axis xyz="0 1 0"/>
    <limit effort="0" lower="-3.139847324337799" upper="3.139847324337799" velocity="1.3962634015954636"/>
  </joint>
  <joint name="J3" type="revolute">
    <origin rpy="0 0 0" xyz="0 0 0.71"/>
    <parent link="J2_link"/>
    <child link="J3_link"/>
    <axis xyz="0 -1 0"/>
    <limit effort="0" lower="-4.71238898038469" upper="4.71238898038469" velocity="2.0943951023931953"/>
  </joint>
  <joint name="J4" type="revolute">
    <origin rpy="0 0 0" xyz="0 0 0.0"/>
    <parent link="J3_link"/>
    <child link="J4_link"/>
    <axis xyz="-1 0 0"/>
    <limit effort="0" lower="-3.3161255787892263" upper="3.3161255787892263" velocity="1.9634954084936207"/>
  </joint>
  <joint name="J5" type="revolute">
    <origin rpy="0 0 0" xyz="0.54 0 0"/>
    <parent link="J4_link"/>
    <child link="J5_link"/>
    <axis xyz="0 -1 0"/>
    <limit effort="0" lower="-3.139847324337799" upper="3.139847324337799" velocity="1.5707963267948966"/>
  </joint>
  <joint name="J6" type="revolute">
    <origin rpy="0 0 0" xyz="0 -0.15 0"/>
    <parent link="J5_link"/>
    <child link="J6_link"/>
    <axis xyz="-1 0 0"/>
    <limit effort="0" lower="-3.9269908169872414" upper="3.9269908169872414" velocity="1.9634954084936207"/>
  </joint>
  <!-- world coords -->
  <link name="wbase"/>
  <joint name="base_link-wbase" type="fixed">
    <origin rpy="0 0 0" xyz="0 0 0.245"/>
    <parent link="base_link"/>
    <child link="wbase"/>
  </joint>
  <!-- flange coords -->
  <link name="flange"/>
  <joint name="J6-flange" type="fixed">
    <origin rpy="0 0 0" xyz="0.16 0 0"/>
    <parent link="J6_link"/>
    <child link="flange"/>
  </joint>
  <!-- flange1 coords -->
  <link name="flange1"/>
  <joint name="flange-flange1" type="fixed">
    <origin rpy="0 1.5707963267948966 0" xyz="0 0 0"/>
    <parent link="flange"/>
    <child link="flange1"/>
  </joint>
  <!-- tcp coords -->
  <link name="tcp"/>
  <joint name="flange1-tcp" type="fixed">
    <origin rpy="0 0 0" xyz="0 0 0"/>
    <parent link="flange1"/>
    <child link="tcp"/>
  </joint>
  <!-- tcp right coord -->
  <link name="tcp_right"/>
  <joint name="tcp-tcp_right" type="fixed">
    <origin rpy="0 0 0" xyz="0 0.012 0.013"/>
    <parent link="tcp"/>
    <child link="tcp_right"/>
  </joint>
  <!-- tcp left coord -->
  <link name="tcp_left"/>
  <joint name="tcp-tcp_left" type="fixed">
    <origin rpy="0 0 0" xyz="0 -0.012 0.013"/>
    <parent link="tcp"/>
    <child link="tcp_left"/>
  </joint>
  <joint name="partent_to_scanner" type="fixed">
    <origin rpy="0 0 3.1415" xyz="0 0 0"/>
    <parent link="flange1"/>
    <child link="scanner"/>
  </joint>
  <link name="scanner">
    <visual>
      <origin rpy="0 0 0" xyz="0 0 .08"/>
      <geometry>
        <box size=".16 .16 .2"/>
      </geometry>
      <material name="purple_scanner">
        <color rgba="0.4 0.0 0.75 1"/>
      </material>
    </visual>
    <collision>
      <origin rpy="0 0 0" xyz="0 0 0.08"/>
      <geometry>
        <box size=".16 .16 .2"/>
      </geometry>
    </collision>
  </link>
  <link name="tool_tcp"/>
  <joint name="tool_tcp_joint" type="fixed">
    <origin rpy="0 1.5707 0" xyz="0.08 0 0.095"/>
    <parent link="scanner"/>
    <child link="tool_tcp"/>
  </joint>
  <!-- other features -->
  <joint name="t1partent_to_tab" type="fixed">
    <origin rpy="0 0 0" xyz="-0.06 .85 0"/>
    <parent link="world"/>
    <child link="t1table"/>
  </joint>
  <link name="t1table">
    <visual>
      <origin rpy="0 0 0" xyz="0 0 0"/>
      <geometry>
        <mesh filename="package://pad_cell_description/urdf/meshes/table.stl"/>
      </geometry>
      <material name="grey_table">
        <color rgba="0.85 0.85 0.85 1"/>
      </material>
    </visual>
    <collision>
      <origin rpy="0 0 0" xyz="0 0 0.47"/>
      <geometry>
        <box size=".76 1.02 .94"/>
      </geometry>
    </collision>
  </link>
  <link name="t1table_top"/>
  <joint name="t1mounting" type="fixed">
    <origin rpy="0 0 0" xyz="0 0 0.92"/>
    <parent link="t1table"/>
    <child link="t1table_top"/>
  </joint>
  <joint name="partent_to_beam" type="fixed">
    <origin rpy="0 0 0" xyz="0.02 -0.05 0"/>
    <parent link="t1table_top"/>
    <child link="beam"/>
  </joint>
  <link name="beam">
    <visual>
      <origin rpy="0 0 0" xyz="0 0 .18"/>
      <geometry>
        <box size=".04 0.04 .36"/>
      </geometry>
      <material name="grey_beam">
        <color rgba=".5 .5 .5 1"/>
      </material>
    </visual>
    <collision>
      <origin rpy="0 0 0" xyz="0 0 .18"/>
      <geometry>
        <box size=".2 0.2 .36"/>
      </geometry>
    </collision>
  </link>
  <joint name="partent_to_turbine" type="fixed">
    <origin rpy="0 0 0" xyz="0.0 0.0 0.36"/>
    <parent link="beam"/>
    <child link="_turbine"/>
  </joint>
  <link name="_turbine">
    <visual>
      <origin rpy="0 0 0" xyz="0 0 0"/>
      <geometry>
        <cylinder length="0.03" radius="0.15"/>
      </geometry>
      <material name="grey_turbine">
        <color rgba="0.8 .8 .8 1"/>
      </material>
    </visual>
    <collision>
      <origin rpy="0 0 0" xyz="0 0 0"/>
      <geometry>
        <cylinder length="0.03" radius="0.15"/>
      </geometry>
    </collision>
  </link>
  <!-- environmental features -->
  <!-- walls and ceiling -->
  <!-- <xacro:wall tf_prefix="w1" parent="world" >
    <origin xyz="-1.4 0 0" rpy="0 0 0"/>
  </xacro:wall>

  <xacro:wall tf_prefix="w2" parent="world" >
    <origin xyz="-1.4 0 2.7" rpy="0 1.5707 0"/>
  </xacro:wall>

  <xacro:wall tf_prefix="w3" parent="world" >
    <origin xyz="0 -2 0" rpy="0 0 1.5707"/>
  </xacro:wall>

  <xacro:pc_desk tf_prefix="" parent="world" >
    <origin xyz="0 -0.85 0" rpy="0 0 0"/>
  </xacro:pc_desk> -->
  <!-- cameras -->
  <!-- <xacro:beam tf_prefix="b1" parent="world" >
    <origin xyz="0 -1.5 2" rpy="0 0 0"/>
  </xacro:beam>

  <xacro:camera tf_prefix="c1" parent="b1beam" >
    <origin xyz="0.1 0 0.2" rpy="-1.5707 0.5 1"/>
  </xacro:camera>

  <xacro:beam tf_prefix="b2" parent="world" >
    <origin xyz="-${x_table} -0.5 2" rpy="0 0 0"/>
  </xacro:beam>

  <xacro:camera tf_prefix="c2" parent="b2beam" >
    <origin xyz="0 0.1 0.2" rpy="-1.5707 1.5707 0"/>
  </xacro:camera>
 -->
</robot>
